Workbook

Sheet Overall Summary
D1: ='Sector_MDAs Summary-Details'!C1 -> Perfomance Delivery Coordination Unit (PDCU), Office of the Executive Governor
A2: January to December 2024 MDA/Sector Summary of Performance on Commitments
A3: S/N | B3: Ministries and Agencies | C3: ='Sector_MDAs Summary-Details'!B3 -> Commitments | D3: ='Sector_MDAs Summary-Details'!C3 -> No. of Outputs | E3: ='Sector_MDAs Summary-Details'!D3 -> No Results to be Delivered | F3: ='Sector_MDAs Summary-Details'!E3 -> Performance for Each Result | G3: ='Sector_MDAs Summary-Details'!F3 -> 0 | H3: ='Sector_MDAs Summary-Details'!G3 -> 0 | I3: ='Sector_MDAs Summary-Details'!H3 -> 0 | J3: ='Sector_MDAs Summary-Details'!I4 -> Below Minimum Expectation | K3: ='Sector_MDAs Summary-Details'!J4 -> Not Assessed | L3: ='Sector_MDAs Summary-Details'!K3 -> Overall Performance | M3: ='Sector_MDAs Summary-Details'!L3 -> 0
A4: 0 | B4: 0 | C4: ='Sector_MDAs Summary-Details'!B4 -> 0 | D4: ='Sector_MDAs Summary-Details'!C4 -> 0 | F4: ='Sector_MDAs Summary-Details'!E4 -> Exceptional | G4: ='Sector_MDAs Summary-Details'!F4 -> Above Expectation | H4: ='Sector_MDAs Summary-Details'!G4 -> Meets Expectation | I4: ='Sector_MDAs Summary-Details'!H4 -> Needs Improvement | L4: ='Sector_MDAs Summary-Details'!K4 -> 0 | M4: ='Sector_MDAs Summary-Details'!L4 -> 0
A5: 0 | B5: 0 | C5: ='Sector_MDAs Summary-Details'!B5 -> 0 | D5: ='Sector_MDAs Summary-Details'!C5 -> 0 | E5: No. of Results | F5: ='Sector_MDAs Summary-Details'!E5 -> Above 100% | G5: ='Sector_MDAs Summary-Details'!F5 -> 70% -100% | H5: ='Sector_MDAs Summary-Details'!G5 -> 60% - 69% | I5: ='Sector_MDAs Summary-Details'!H5 -> 40% - 59% | J5: ='Sector_MDAs Summary-Details'!I5 -> Below 40% | K5: ='Sector_MDAs Summary-Details'!J5 -> N/A | L5: ='Sector_MDAs Summary-Details'!K5 -> Performance | M5: ='Sector_MDAs Summary-Details'!L5 -> Rating
A7: 1 | B7: Youth Empowerment and Employment Agency | C7: 1 | D7: ='Sector_MDAs Summary-Details'!C9 -> 9 | E7: ='Sector_MDAs Summary-Details'!D9 -> 20 | F7: ='Sector_MDAs Summary-Details'!E9 -> 5 | G7: ='Sector_MDAs Summary-Details'!F9 -> 5 | H7: ='Sector_MDAs Summary-Details'!G9 -> 2 | I7: ='Sector_MDAs Summary-Details'!H9 -> 5 | J7: ='Sector_MDAs Summary-Details'!I9 -> 2 | K7: ='Sector_MDAs Summary-Details'!J9 -> 1 | ... M7: ='Sector_MDAs Summary-Details'!L9 -> Very Good (Above Expectations) | N7: =E7-(F7+G7+H7+I7+J7+K7) -> 0
A8: 2 | B8: Ministry of Commerce, Industry, Cooperatives & Tourism | C8: 10 | D8: ='Sector_MDAs Summary-Details'!C22 -> 19 | E8: ='Sector_MDAs Summary-Details'!D22 -> 31 | F8: ='Sector_MDAs Summary-Details'!E22 -> 4 | G8: ='Sector_MDAs Summary-Details'!F22 -> 6 | H8: ='Sector_MDAs Summary-Details'!G22 -> 0 | I8: ='Sector_MDAs Summary-Details'!H22 -> 1 | J8: ='Sector_MDAs Summary-Details'!I22 -> 15 | K8: ='Sector_MDAs Summary-Details'!J22 -> 5 | ... M8: ='Sector_MDAs Summary-Details'!L22 -> Fair (Needs Improvement) | N8: =E8-(F8+G8+H8+I8+J8+K8) -> 0
A9: 3 | B9: Ministry of Women Affairs and Social Development | C9: 4 | D9: ='Sector_MDAs Summary-Details'!C30 -> 8 | E9: ='Sector_MDAs Summary-Details'!D30 -> 19 | F9: ='Sector_MDAs Summary-Details'!E30 -> 4 | G9: ='Sector_MDAs Summary-Details'!F30 -> 4 | H9: ='Sector_MDAs Summary-Details'!G30 -> 2 | I9: ='Sector_MDAs Summary-Details'!H30 -> 3 | J9: ='Sector_MDAs Summary-Details'!I30 -> 4 | K9: ='Sector_MDAs Summary-Details'!J30 -> 2 | L9: ='Sector_MDAs Summary-Details'!K30 -> 0.62036672 | M9: Good (Meets Expectations) | N9: =E9-(F9+G9+H9+I9+J9+K9) -> 0
A10: 4 | B10: Ministry for Local Govt. & Community Development | C10: 5 | D10: ='Sector_MDAs Summary-Details'!C38 -> 6 | E10: ='Sector_MDAs Summary-Details'!D38 -> 8 | F10: ='Sector_MDAs Summary-Details'!E38 -> 0 | G10: ='Sector_MDAs Summary-Details'!F38 -> 5 | H10: ='Sector_MDAs Summary-Details'!G38 -> 1 | I10: ='Sector_MDAs Summary-Details'!H38 -> 1 | J10: ='Sector_MDAs Summary-Details'!I38 -> 1 | K10: ='Sector_MDAs Summary-Details'!J38 -> 0 | ... M10: ='Sector_MDAs Summary-Details'!L38 -> Very Good (Above Expectations) | N10: =E10-(F10+G10+H10+I10+J10+K10) -> 0
A11: 5 | B11: Ministry of Environment | C11: 6 | D11: ='Sector_MDAs Summary-Details'!C47 -> 31 | E11: ='Sector_MDAs Summary-Details'!D47 -> 47 | F11: ='Sector_MDAs Summary-Details'!E47 -> 12 | G11: ='Sector_MDAs Summary-Details'!F47 -> 21 | H11: ='Sector_MDAs Summary-Details'!G47 -> 3 | I11: ='Sector_MDAs Summary-Details'!H47 -> 3 | J11: ='Sector_MDAs Summary-Details'!I47 -> 7 | K11: ='Sector_MDAs Summary-Details'!J47 -> 1 | ... M11: ='Sector_MDAs Summary-Details'!L47 -> Very Good (Above Expectations) | N11: =E11-(F11+G11+H11+I11+J11+K11) -> 0
A12: 6 | B12: Ministry of Basic Education | C12: 9 | D12: ='Sector_MDAs Summary-Details'!C59 -> 10 | E12: ='Sector_MDAs Summary-Details'!D59 -> 19 | F12: ='Sector_MDAs Summary-Details'!E59 -> 6 | G12: ='Sector_MDAs Summary-Details'!F59 -> 6 | H12: ='Sector_MDAs Summary-Details'!G59 -> 0 | I12: ='Sector_MDAs Summary-Details'!H59 -> 2 | J12: ='Sector_MDAs Summary-Details'!I59 -> 5 | K12: ='Sector_MDAs Summary-Details'!J59 -> 0 | ... M12: ='Sector_MDAs Summary-Details'!L59 -> Good (Meets Expectations) | N12: =E12-(F12+G12+H12+I12+J12+K12) -> 0
A13: 7 | B13: Ministry of Higher Education | C13: 11 | D13: ='Sector_MDAs Summary-Details'!C75 -> 13 | E13: ='Sector_MDAs Summary-Details'!D75 -> 23 | F13: ='Sector_MDAs Summary-Details'!E75 -> 9 | G13: ='Sector_MDAs Summary-Details'!F75 -> 11 | H13: ='Sector_MDAs Summary-Details'!G75 -> 1 | I13: ='Sector_MDAs Summary-Details'!H75 -> 0 | J13: ='Sector_MDAs Summary-Details'!I75 -> 1 | K13: ='Sector_MDAs Summary-Details'!J75 -> 1 | ... M13: ='Sector_MDAs Summary-Details'!L75 -> Very Good (Above Expectations) | N13: =E13-(F13+G13+H13+I13+J13+K13) -> 0
A14: 8 | B14: Ministry of Finance/Jigawa Internal Revenue Service | C14: 1 | D14: ='Sector_MDAs Summary-Details'!C80 -> 3 | E14: ='Sector_MDAs Summary-Details'!D80 -> 18 | F14: ='Sector_MDAs Summary-Details'!E80 -> 8 | G14: ='Sector_MDAs Summary-Details'!F80 -> 7 | H14: ='Sector_MDAs Summary-Details'!G80 -> 0 | I14: ='Sector_MDAs Summary-Details'!H80 -> 2 | J14: ='Sector_MDAs Summary-Details'!I80 -> 1 | K14: ='Sector_MDAs Summary-Details'!J80 -> 0 | ... M14: ='Sector_MDAs Summary-Details'!L80 -> Very Good (Above Expectations) | N14: =E14-(F14+G14+H14+I14+J14+K14) -> 0
A15: 9 | B15: Jigawa State Investment Promotion Agency (InvestJigawa) | C15: 3 | D15: ='Sector_MDAs Summary-Details'!C90 -> 10 | E15: ='Sector_MDAs Summary-Details'!D90 -> 22 | F15: ='Sector_MDAs Summary-Details'!E90 -> 6 | G15: ='Sector_MDAs Summary-Details'!F90 -> 5 | H15: ='Sector_MDAs Summary-Details'!G90 -> 0 | I15: ='Sector_MDAs Summary-Details'!H90 -> 2 | J15: ='Sector_MDAs Summary-Details'!I90 -> 5 | K15: ='Sector_MDAs Summary-Details'!J90 -> 4 | ... M15: ='Sector_MDAs Summary-Details'!L90 -> Good (Meets Expectations) | N15: =E15-(F15+G15+H15+I15+J15+K15) -> 0
A16: 10 | B16: Ministry of Lands, Housing, Urban & Regional Planning | C16: 4 | D16: ='Sector_MDAs Summary-Details'!C92 -> 0 | E16: ='Sector_MDAs Summary-Details'!D98 -> 21 | F16: ='Sector_MDAs Summary-Details'!E98 -> 0 | G16: ='Sector_MDAs Summary-Details'!F98 -> 6 | H16: ='Sector_MDAs Summary-Details'!G98 -> 1 | I16: ='Sector_MDAs Summary-Details'!H98 -> 1 | J16: ='Sector_MDAs Summary-Details'!I98 -> 12 | K16: ='Sector_MDAs Summary-Details'!J98 -> 1 | L16: ='Sector_MDAs Summary-Details'!K98 -> 0.45484224 | M16: ='Sector_MDAs Summary-Details'!L98 -> Fairly Ok (Needs Improvement) | N16: =E16-(F16+G16+H16+I16+J16+K16) -> 0
A17: 11 | B17: Ministry of Water Resources / Water Sector | C17: 3 | D17: ='Sector_MDAs Summary-Details'!C104 -> 10 | E17: ='Sector_MDAs Summary-Details'!D104 -> 36 | F17: ='Sector_MDAs Summary-Details'!E104 -> 6 | G17: ='Sector_MDAs Summary-Details'!F104 -> 14 | H17: ='Sector_MDAs Summary-Details'!G104 -> 2 | I17: ='Sector_MDAs Summary-Details'!H104 -> 2 | J17: ='Sector_MDAs Summary-Details'!I104 -> 12 | K17: ='Sector_MDAs Summary-Details'!J104 -> 0 | ... M17: ='Sector_MDAs Summary-Details'!L104 -> Good (Meets Expectations) | N17: =E17-(F17+G17+H17+I17+J17+K17) -> 0
A18: 12 | B18: Ministry of Works | C18: 1 | D18: ='Sector_MDAs Summary-Details'!C114 -> 1 | E18: ='Sector_MDAs Summary-Details'!D114 -> 7 | F18: ='Sector_MDAs Summary-Details'!E114 -> 4 | G18: ='Sector_MDAs Summary-Details'!F114 -> 0 | H18: ='Sector_MDAs Summary-Details'!G114 -> 0 | I18: ='Sector_MDAs Summary-Details'!H114 -> 2 | J18: ='Sector_MDAs Summary-Details'!I114 -> 1 | K18: ='Sector_MDAs Summary-Details'!J114 -> 0 | ... M18: ='Sector_MDAs Summary-Details'!L114 -> Very Good (Above Expectations) | N18: =E18-(F18+G18+H18+I18+J18+K18) -> 0
A19: 13 | B19: Min. of Power & Energy (State Electricity Board) | C19: 1 | D19: ='Sector_MDAs Summary-Details'!C119 -> 3 | E19: ='Sector_MDAs Summary-Details'!D119 -> 8 | F19: ='Sector_MDAs Summary-Details'!E119 -> 2 | G19: ='Sector_MDAs Summary-Details'!F119 -> 0 | H19: ='Sector_MDAs Summary-Details'!G119 -> 0 | I19: ='Sector_MDAs Summary-Details'!H119 -> 2 | J19: ='Sector_MDAs Summary-Details'!I119 -> 2 | K19: ='Sector_MDAs Summary-Details'!J119 -> 2 | ... M19: ='Sector_MDAs Summary-Details'!L119 -> Fairly Ok (Needs Improvement) | N19: =E19-(F19+G19+H19+I19+J19+K19) -> 0
A20: 14 | B20: Office of the Head of the State Civil Service | C20: 4 | D20: ='Sector_MDAs Summary-Details'!C130 -> 7 | E20: ='Sector_MDAs Summary-Details'!D130 -> 24 | F20: ='Sector_MDAs Summary-Details'!E130 -> 7 | G20: ='Sector_MDAs Summary-Details'!F130 -> 3 | H20: ='Sector_MDAs Summary-Details'!G130 -> 0 | I20: ='Sector_MDAs Summary-Details'!H130 -> 1 | J20: ='Sector_MDAs Summary-Details'!I130 -> 10 | K20: ='Sector_MDAs Summary-Details'!J130 -> 3 | ... M20: ='Sector_MDAs Summary-Details'!L130 -> Fairly Ok (Needs Improvement) | N20: =E20-(F20+G20+H20+I20+J20+K20) -> 0
A21: 15 | B21: Ministry of Agriculture / Agricultural Sector | C21: 12 | D21: ='Sector_MDAs Summary-Details'!C146 -> 24 | E21: ='Sector_MDAs Summary-Details'!D146 -> 67 | F21: ='Sector_MDAs Summary-Details'!E146 -> 12 | G21: ='Sector_MDAs Summary-Details'!F146 -> 20 | H21: ='Sector_MDAs Summary-Details'!G146 -> 4 | I21: ='Sector_MDAs Summary-Details'!H146 -> 14 | J21: ='Sector_MDAs Summary-Details'!I146 -> 13 | K21: ='Sector_MDAs Summary-Details'!J146 -> 4 | ... M21: ='Sector_MDAs Summary-Details'!L146 -> Good (Meets Expectations) | N21: =E21-(F21+G21+H21+I21+J21+K21) -> 0
A22: 16 | B22: Ministry of Special Duties | C22: 3 | D22: ='Sector_MDAs Summary-Details'!C152 -> 4 | E22: ='Sector_MDAs Summary-Details'!D152 -> 11 | F22: ='Sector_MDAs Summary-Details'!E152 -> 2 | G22: ='Sector_MDAs Summary-Details'!F152 -> 3 | H22: ='Sector_MDAs Summary-Details'!G152 -> 0 | I22: ='Sector_MDAs Summary-Details'!H152 -> 1 | J22: ='Sector_MDAs Summary-Details'!I152 -> 4 | K22: ='Sector_MDAs Summary-Details'!J152 -> 1 | ... M22: ='Sector_MDAs Summary-Details'!L152 -> Fairly Ok (Needs Improvement) | N22: =E22-(F22+G22+H22+I22+J22+K22) -> 0
A23: 17 | B23: Ministry of Budget and Economic Planning | C23: 4 | D23: ='Sector_MDAs Summary-Details'!C160 -> 7 | E23: ='Sector_MDAs Summary-Details'!D160 -> 18 | F23: ='Sector_MDAs Summary-Details'!E160 -> 1 | G23: ='Sector_MDAs Summary-Details'!F160 -> 8 | H23: ='Sector_MDAs Summary-Details'!G160 -> 0 | I23: ='Sector_MDAs Summary-Details'!H160 -> 3 | J23: ='Sector_MDAs Summary-Details'!I160 -> 4 | K23: ='Sector_MDAs Summary-Details'!J160 -> 2 | ... M23: ='Sector_MDAs Summary-Details'!L160 -> Good (Meets Expectations) | N23: =E23-(F23+G23+H23+I23+J23+K23) -> 0
A24: 18 | B24: Ministry of Justice | C24: 1 | D24: ='Sector_MDAs Summary-Details'!C163 -> 9 | E24: ='Sector_MDAs Summary-Details'!D163 -> 29 | F24: ='Sector_MDAs Summary-Details'!E163 -> 6 | G24: ='Sector_MDAs Summary-Details'!F163 -> 8 | H24: ='Sector_MDAs Summary-Details'!G163 -> 1 | I24: ='Sector_MDAs Summary-Details'!H163 -> 2 | J24: ='Sector_MDAs Summary-Details'!I163 -> 11 | K24: ='Sector_MDAs Summary-Details'!J163 -> 1 | ... M24: ='Sector_MDAs Summary-Details'!L163 -> Fairly Ok (Needs Improvement) | N24: =E24-(F24+G24+H24+I24+J24+K24) -> 0
A25: 19 | B25: Office of the SSG (Security) | C25: 8 | D25: ='Sector_MDAs Summary-Details'!C183 -> 9 | E25: ='Sector_MDAs Summary-Details'!D183 -> 19 | F25: ='Sector_MDAs Summary-Details'!E183 -> 5 | G25: ='Sector_MDAs Summary-Details'!F183 -> 2 | H25: ='Sector_MDAs Summary-Details'!G183 -> 0 | I25: ='Sector_MDAs Summary-Details'!H183 -> 0 | J25: ='Sector_MDAs Summary-Details'!I183 -> 3 | K25: ='Sector_MDAs Summary-Details'!J183 -> 9 | ... M25: ='Sector_MDAs Summary-Details'!L183 -> Good (Meets Expectations) | N25: =E25-(F25+G25+H25+I25+J25+K25) -> 0
A26: 20 | B26: Ministry of Health / Health Sector | C26: 6 | D26: ='Sector_MDAs Summary-Details'!C192 -> 8 | E26: ='Sector_MDAs Summary-Details'!D192 -> 57 | F26: ='Sector_MDAs Summary-Details'!E192 -> 5 | G26: ='Sector_MDAs Summary-Details'!F192 -> 18 | H26: ='Sector_MDAs Summary-Details'!G192 -> 7 | I26: ='Sector_MDAs Summary-Details'!H192 -> 10 | J26: ='Sector_MDAs Summary-Details'!I192 -> 14 | K26: ='Sector_MDAs Summary-Details'!J192 -> 3 | ... M26: ='Sector_MDAs Summary-Details'!L192 -> Fairly Ok (Needs Improvement) | N26: =E26-(F26+G26+H26+I26+J26+K26) -> 0
A27: 21 | B27: Ministry of Information | C27: 5 | D27: ='Sector_MDAs Summary-Details'!C200 -> 6 | E27: ='Sector_MDAs Summary-Details'!D200 -> 28 | F27: ='Sector_MDAs Summary-Details'!E200 -> 1 | G27: ='Sector_MDAs Summary-Details'!F200 -> 19 | H27: ='Sector_MDAs Summary-Details'!G200 -> 0 | I27: ='Sector_MDAs Summary-Details'!H200 -> 2 | J27: ='Sector_MDAs Summary-Details'!I200 -> 5 | K27: ='Sector_MDAs Summary-Details'!J200 -> 1 | ... M27: ='Sector_MDAs Summary-Details'!L200 -> Good (Meets Expectations) | N27: =E27-(F27+G27+H27+I27+J27+K27) -> 0
C29: =SUM(C6:C28) -> 102 | D29: =SUM(D6:D28) -> 197 | E29: =SUM(E6:E28) -> 532 | F29: =SUM(F6:F28) -> 105 | G29: =SUM(G6:G28) -> 171 | H29: =SUM(H6:H28) -> 24 | I29: =SUM(I6:I28) -> 59 | J29: =SUM(J6:J28) -> 132 | K29: =SUM(K6:K28) -> 41 | L29: =AVERAGE(L7:L28) -> 0.6484455

Sheet Grand Summary-Sector_MDAs+
A1: Perfomance Delivery Coordination Unit (PDCU), Office of the Executive Governor
A2: 2024 Fiscal Year Snapshot View of MDA/Sector Performance (January to Decemeber)
A3: S/N | B3: Names of MDAs / Sector | C3: No. of Commitments | D3: No. of Outputs | E3: No Results to be Delivered | F3: Overall Performance
F4: Performance at Mid-Year | G4: Fully Performance | H4: Fully Performance Rating
A5: 1 | B5: Youth Empowerment and Employment Agency | C5: ='Overall Summary'!C27 -> 5 | D5: 9 | E5: ='[1]MDA_Sector Summary'!D8 -> 20 | F5: 0.4378104 | G5: ='15. Empowerment'!H34 -> 0.72931604 | H5: Very Good - Above Expectations | I5: 1 | J5: 0.68533333
A6: 2 | B6: Min. of Commerce, Industries & Co-operatives | C6: ='Overall Summary'!C13 -> 11 | D6: 14 | E6: 27 | F6: 0.287 | G6: ='8. Min. of Comm'!H59 -> 0.4496148 | H6: Fair - Needs Improvement | I6: 2 | J6: 0.51601965
A7: 3 | B7: Ministry of Women Affairs & Social Development | C7: ='Overall Summary'!C24 -> 1 | D7: 8 | E7: 16 | F7: 0.36335417 | G7: ='18. Min. of Women Affrs'!H34 -> 0.62036672 | H7: Good Meet s Expectations | I7: 3 | J7: 0.56356926
A8: 4 | B8: Ministry of Local Government | C8: ='Overall Summary'!C21 -> 12 | D8: 6 | E8: 8 | F8: 0.47737778 | G8: ='4. Min. of LG'!H29 -> 0.70770833 | H8: Very Good - Above Expectations | I8: 4 | J8: 0.64717905
A9: 5 | B9: Ministry of Environment | C9: ='Overall Summary'!C14 -> 1 | D9: ='[1]MDA_Sector Summary'!C43 -> 31 | E9: ='[1]MDA_Sector Summary'!D43 -> 47 | F9: 0.36724017 | G9: ='19. Min. of Env'!H71 -> 0.76182238 | H9: Very Good - Above Expectations | I9: 5 | J9: 0.6888195
A10: 6 | B10: Ministry of Basic Education | C10: ='Overall Summary'!C11 -> 6 | D10: 10 | E10: 16 | F10: 0.24 | G10: ='13. Min. of Basic Edu'!H44 -> 0.6888195 | H10: Good Meet s Expectations | I10: 6 | J10: 0.59988095
A11: 7 | B11: Min. of Higher Education, Science & Technology | C11: ='Overall Summary'!C17 -> 3 | D11: 13 | E11: 23 | F11: 0.50318182 | G11: ='14. Min. of Higher Edu'!H50 -> 0.9333092 | H11: Very Good - Above Expectations | I11: 7 | J11: 0.4496148
A12: 8 | B12: Ministry of Finance (Internal Revenue Service) | C12: ='Overall Summary'!C15 -> 3 | D12: 3 | E12: 17 | F12: 0.441 | G12: ='MoF-JIRS'!H25 -> 0.86473684 | H12: Very Good - Above Expectations | I12: 8 | J12: 0.76182238
A13: 9 | B13: State Investment Promotion Agency | C13: ='Overall Summary'!C26 -> 6 | D13: ='[1]MDA_Sector Summary'!C82 -> 10 | E13: ='[1]MDA_Sector Summary'!D88 -> 20 | F13: 0.425 | G13: ='16. JigawaInvest'!H34 -> 0.66296542 | H13: Good Meet s Expectations | I13: 9 | J13: 0.86473684
A14: 10 | B14: Min. of Lands, Housing and Urban Development | C14: ='Overall Summary'!C20 -> 4 | D14: 10 | E14: 20 | F14: 0.27721461 | G14: ='20. Min. of Land'!H37 -> 0.45484224 | H14: Fair - Needs Improvement | I14: 10 | J14: 0.65406464
A15: 11 | B15: Ministry of Water Resources | C15: ='Overall Summary'!C23 -> 4 | D15: 10 | E15: ='[1]MDA_Sector Summary'!D94 -> 36 | F15: 0.39566667 | G15: ='10. Min. of Water SS'!H49 -> 0.63785681 | H15: Good Meet s Expectations | I15: 11 | J15: 0.9333092
A16: 12 | B16: Ministry of Works & Transport | C16: ='Overall Summary'!C25 -> 8 | D16: 1 | E16: ='[1]MDA_Sector Summary'!D98 -> 7 | F16: 0.319 | G16: ='6. Min. of Works'!I16 -> 0.76428571 | H16: Very Good - Above Expectations | I16: 12 | J16: 0.65038752
A17: 13 | B17: Ministry of Power and Energy | C17: ='Overall Summary'!C22 -> 3 | D17: 3 | E17: 8 | F17: 0.2528 | G17: ='7. Power'!H14 -> 0.56083333 | H17: Fair - Needs Improvement | I17: 13 | J17: 0.56943897
A18: 14 | B18: Office of the Head of the State Civil Service | C18: ='Overall Summary'!C8 -> 10 | D18: 4 | E18: 24 | F18: 0.35368634 | G18: ='1. OHOS'!H37 -> 0.51601965 | H18: Fair - Needs Improvement | I18: 14 | J18: 0.45484224
A19: 15 | B19: Ministry of Agriculture & Natural Resources | C19: ='Overall Summary'!C10 -> 5 | D19: 25 | E19: 64 | F19: 0.455 | G19: ='9. Min. of Agric'!H98 -> 0.64717905 | H19: Good Meet s Expectations | I19: 15 | J19: 0.70770833
A20: 16 | B20: Ministry For Special Duties | C20: ='Overall Summary'!C9 -> 4 | D20: ='[1]MDA_Sector Summary'!C132 -> 4 | E20: ='[1]MDA_Sector Summary'!D132 -> 9 | F20: 0.42 | G20: ='3. Min. of Special Duties'!I28 -> 0.56356926 | H20: Fair - Needs Improvement | I20: 16 | J20: 0.56083333
A21: 17 | B21: Ministry of Budget and Economic Planning | C21: ='Overall Summary'!C12 -> 9 | D21: 7 | E21: 22 | F21: 0.39816162 | G21: ='5. Min. of Budget'!H32 -> 0.59988095 | H21: Good Meet s Expectations | I21: 17 | J21: 0.63785681
A22: 18 | B22: Ministry of Justice | C22: ='Overall Summary'!C19 -> 1 | D22: 9 | E22: 29 | F22: 0.4141434 | G22: ='21. MoJustice'!H34 -> 0.56943897 | H22: Fair - Needs Improvement | I22: 18 | J22: 0.62036672
A23: 19 | B23: Office of the Secretary to the State Government | C23: ='Overall Summary'!C7 -> 1 | D23: 4 | E23: 14 | F23: 0.22222222 | G23: ='Sector_MDAs Summary-Details'!K183 -> 0.68533333 | H23: Good Meet s Expectations | I23: 19 | J23: 0.76428571
A24: 20 | B24: Ministry of Health | C24: ='Overall Summary'!C16 -> 4 | D24: ='[1]MDA_Sector Summary'!C163 -> 8 | E24: ='[1]MDA_Sector Summary'!D163 -> 60 | F24: 0.41021999 | G24: ='11. Min. of Health'!H80 -> 0.65406464 | H24: Good Meet s Expectations | I24: 20 | J24: 0.66296542
A25: 21 | B25: Min. of Information Youths, Sports and Culture | C25: ='Overall Summary'!C18 -> 1 | D25: ='[1]MDA_Sector Summary'!C171 -> 6 | E25: ='[1]MDA_Sector Summary'!D171 -> 26 | F25: 0.45837963 | G25: ='12. Min. of Infor'!H45 -> 0.65038752 | H25: Good Meet s Expectations | I25: 21 | J25: 0.72931604
A26: 22 | B26: Overall State Performance | C26: ='Overall Summary'!C28 -> 0 | D26: =SUM(D5:D25) -> 195 | E26: =SUM(E5:E25) -> 513 | F26: 0.37706947 | G26: =AVERAGE(G5:G25) -> 0.65344527 | H26: Good Meet s Expectations | J26: 0.65344527
B34: =1109+4556+2202 -> 7867

Sheet Sector_MDAs Summary-Details
C1: Perfomance Delivery Coordination Unit (PDCU), Office of the Executive Governor
A2: January to December 2024 MDA/Sector Summary of Performance on Commitments
A3: S/N | B3: Commitments | C3: No. of Outputs | D3: No Results to be Delivered | E3: Performance for Each Result | K3: Overall Performance | M3: r
E4: Exceptional | F4: Above Expectation | G4: Meets Expectation | H4: Needs Improvement | I4: Below Minimum Expectation | J4: Not Assessed | N4: Check
E5: Above 100% | F5: 70% -100% | G5: 60% - 69% | H5: 40% - 59% | I5: Below 40% | J5: N/A | K5: Performance | L5: Rating
M6: A Good Performance with significant improvement compared to mid0year performance of 44%
B7: Youth Empowerment and Employment Agency
A8: 1 | B8: Employment Generation and Youth Empowerment for Productivity and Sustainable Means of Livelihoods for the People of Jigawa State. | C8: 9 | D8: 20 | E8: 5 | F8: 5 | G8: 2 | H8: 5 | I8: 2 | J8: 1 | K8: ='15. Empowerment'!H34 -> 0.72931604 | L8: Very Good Performance
C9: =C8 -> 9 | D9: =D8 -> 20 | E9: =E8 -> 5 | F9: =F8 -> 5 | G9: =G8 -> 2 | H9: =H8 -> 5 | I9: =I8 -> 2 | J9: =J8 -> 1 | K9: =K8 -> 0.72931604 | L9: Very Good (Above Expectations)
B11: Min. of Commerce, Industry, Cooperatives & Tourism
A12: 1 | B12: Promoting of MSMSEs and Cooperatives | C12: 4 | D12: 6 | E12: 1 | F12: 2 | G12: 0 | H12: 1 | I12: 2 | J12: 0 | K12: ='8. Min. of Comm'!I14 -> 0.56199473 | L12: Fair (Needs Improvement) | M12: =D12-E12-F12-G12-H12-I12-J12 -> 0
A13: 2 | B13: Revitalization of Maigatari EPZ | C13: 3 | D13: 9 | E13: 1 | F13: 1 | G13: 0 | H13: 0 | I13: 5 | J13: 2 | K13: ='8. Min. of Comm'!I25 -> 0.32124517 | L13: Unsatisfactory (Below Minimum Requirement) | M13: =D13-E13-F13-G13-H13-I13-J13 -> 0
A14: 3 | B14: Trade Fairs | C14: 1 | D14: 2 | E14: 0 | F14: 0 | G14: 0 | H14: 0 | I14: 0 | J14: 2 | K14: ='8. Min. of Comm'!I29 -> NA | L14: Not Assessed | M14: =D14-E14-F14-G14-H14-I14-J14 -> 0
A15: 4 | B15: Tourism Development | C15: 1 | D15: 2 | E15: 0 | F15: 2 | G15: 0 | H15: 0 | I15: 0 | J15: 0 | K15: ='8. Min. of Comm'!I33 -> 0.82465009 | L15: Very Good (Above Expectation) | M15: =D15-E15-F15-G15-H15-I15-J15 -> 0
A16: 5 | B16: Access to Financing | C16: 1 | D16: 2 | E16: 2 | F16: 0 | G16: 0 | H16: 0 | I16: 0 | J16: 0 | K16: ='8. Min. of Comm'!I37 -> 1.01 | L16: Distinction (Exceptional) | M16: =D16-E16-F16-G16-H16-I16-J16 -> 0
A17: 6 | B17: Export Promotion - Increase Market Access and International Trade Opportunities | C17: 2 | D17: 2 | E17: 0 | F17: 1 | H17: 0 | I17: 1 | J17: 0 | K17: ='8. Min. of Comm'!I41 -> 0.45 | L17: Fair (Needs Improvement) | M17: =D17-E17-F17-G17-H17-I17-J17 -> 0
A18: 7 | B18: Support the operation of Jigawa State Chamber of Commerce to drive the growth of Trade and Industries in the State. | C18: 2 | D18: 2 | E18: 0 | F18: 0 | G18: 0 | H18: 0 | I18: 2 | J18: 0 | K18: ='8. Min. of Comm'!I45 -> 0 | L18: Unsatisfactory (Below Minimum Requirement) | M18: =D18-E18-F18-G18-H18-I18-J18 -> 0
A19: 8 | B19: Capitalize Coops, Agric-based Association and Social Enterprises Development | C19: 1 | D19: 2 | E19: 0 | F19: 0 | G19: 0 | H19: 0 | I19: 1 | J19: 1 | K19: ='8. Min. of Comm'!$I$49 -> 0.3 | L19: Unsatisfactory (Below Minimum Requirement) | M19: =D19-E19-F19-G19-H19-K19-J19 -> 0.7
A20: 9 | B20: Development / Modernzation of Markets in the State to Support Trading Activities and Expand Revenue Generation | C20: 2 | D20: 2 | E20: 0 | F20: 0 | G20: 0 | H20: 0 | I20: 2 | J20: 0 | K20: ='8. Min. of Comm'!I53 -> 0.43333333 | L20: Fair (Needs Improvement) | M20: =D20-E20-F20-G20-H20-I20-J20 -> 0
A21: 10 | B21: Development / Modernzation of Markets in the State to Support Trading Activities and Expand Revenue Generation | C21: 2 | D21: 2 | E21: 0 | F21: 0 | G21: 0 | H21: 0 | I21: 2 | J21: 0 | K21: ='8. Min. of Comm'!I58 -> 0.16666667 | L21: Unsatisfactory (Below Minimum Requirement) | M21: =D21-E21-F21-G21-H21-I21-J21 -> 0
C22: =SUM(C12:C21) -> 19 | D22: =SUM(D12:D21) -> 31 | E22: =SUM(E12:E21) -> 4 | F22: =SUM(F12:F21) -> 6 | G22: =SUM(G12:G21) -> 0 | H22: =SUM(H12:H21) -> 1 | I22: =SUM(I12:I21) -> 15 | J22: =SUM(J12:J21) -> 5 | K22: ='8. Min. of Comm'!H59 -> 0.4496148 | L22: Fair (Needs Improvement) | M22: =D22-E22-F22-G22-H22-I22-J22 -> 0
B24: Ministry of Women Affairs and Social Development
A25: 1 | B25: Pursuit of targeted women empowerment programmes for job and employment creation | C25: 2 | D25: 5 | E25: 1 | F25: 2 | G25: 0 | H25: 1 | I25: 0 | J25: 1 | K25: ='18. Min. of Women Affrs'!I10 -> 0.79 | L25: Very Good (Above Expectations_
A26: 2 | B26: Evolution of new social protection programs along the Life Cycle | C26: 4 | D26: 8 | E26: 3 | F26: 1 | G26: 1 | H26: 1 | I26: 2 | J26: 0 | K26: ='18. Min. of Women Affrs'!I21 -> 0.67333333 | L26: Good (Meets Expectations)
A27: 3 | B27: Develop and implement policies on the protection, survival & development of women and children to address concerns on the Situation of Children in Jigawa State | C27: 1 | D27: 3 | E27: 0 | F27: 0 | G27: 0 | H27: 1 | I27: 2 | J27: 0 | K27: ='18. Min. of Women Affrs'!I27 -> 0.16271777 | L27: Unsatisfactory (Below Minimum Requirement)
A28: 4 | B28: Sustained improvements in Social Welfare Institutions in the State | C28: 1 | D28: 3 | E28: 0 | F28: 1 | G28: 1 | H28: 0 | I28: 0 | J28: 1 | K28: ='18. Min. of Women Affrs'!I33 -> 0.7815 | L28: Very Good (Above Expectations_
E29: Above 100% | F29: 70% -100% | G29: 60% - 69% | H29: 40% - 59% | I29: Below 40% | J29: N/A
C30: =SUM(C25:C28) -> 8 | D30: =SUM(D25:D28) -> 19 | E30: =SUM(E25:E28) -> 4 | F30: =SUM(F25:F28) -> 4 | G30: =SUM(G25:G28) -> 2 | H30: =SUM(H25:H28) -> 3 | I30: =SUM(I25:I28) -> 4 | J30: =SUM(J25:J28) -> 2 | K30: ='18. Min. of Women Affrs'!H34 -> 0.62036672 | L30: Good (Meets Expectations)
B32: Ministry for Local Govt. & Community Development
A33: 1 | B33: Strengthen Community Based Security Architecture | C33: 1 | D33: 1 | E33: 0 | F33: 1 | G33: 0 | H33: 0 | I33: 0 | J33: 0 | K33: ='4. Min. of LG'!I8 -> 1.01 | L33: Distinction (Exceptional
A34: 2 | B34: Launch of Community Peace Initiative (CPI) for improve service delivery and Community Development | C34: 1 | D34: 1 | E34: 0 | F34: 0 | G34: 0 | H34: 1 | I34: 0 | J34: 0 | K34: ='4. Min. of LG'!I13 -> 0.46 | L34: Fair (Needs Improvement)
A35: 3 | B35: Commitment-3: Create an Elders Advisory Committee (ELCO) in every Local Government to advise Government on various government programs and implementation strategies for development. | C35: 1 | D35: 1 | E35: 0 | F35: 0 | G35: 1 | H35: 0 | I35: 0 | J35: 0 | K35: ='4. Min. of LG'!I16 -> 0.6 | L35: Good (Meets Expectations)
A36: 4 | B36: Commitment-4: Entrench an effective financial management system alongside improved policy and strategy across all the Local Governments with the support and collaboration with Development Partners. | C36: 2 | D36: 2 | E36: 0 | F36: 2 | G36: 0 | H36: 0 | I36: 0 | J36: 0 | K36: ='4. Min. of LG'!I20 -> 0.8375 | L36: Very Good (Above Expectations)
A37: 5 | B37: Commitment-5: Sustain street light maintenance across all the 27 LGAs | C37: 1 | D37: 3 | E37: 0 | F37: 2 | G37: 0 | H37: 0 | I37: 1 | J37: 0 | K37: ='4. Min. of LG'!I27 -> 0.63888889 | L37: Good (Meets Expectations)
C38: =SUM(C33:C37) -> 6 | D38: =SUM(D33:D37) -> 8 | E38: =SUM(E33:E37) -> 0 | F38: =SUM(F33:F37) -> 5 | G38: =SUM(G33:G37) -> 1 | H38: =SUM(H33:H37) -> 1 | I38: =SUM(I33:I37) -> 1 | J38: =SUM(J33:J37) -> 0 | K38: ='4. Min. of LG'!H29 -> 0.70770833 | L38: Very Good (Above Expectations)
B40: Ministry of Environment
A41: 1 | B41: Take appropriate proactive measures to address some critical areas of environmental degradation. | C41: 4 | D41: 7 | E41: 3 | F41: 2 | G41: 1 | H41: 1 | I41: 0 | J41: 0 | K41: ='19. Min. of Env'!I13 -> 0.81721088 | L41: Very Good (Above Expectations)
A42: 2 | B42: Take action to address desert encroachment and improved vegetation cover | C42: 7 | D42: 7 | E42: 1 | F42: 5 | G42: 0 | H42: 1 | I42: 0 | J42: 0 | K42: ='19. Min. of Env'!I23 -> 0.8904601 | L42: Very Good (Above Expectations)
A43: 3 | B43: Mobilize and Leverage on External Support from Development Partners to Address issues on Environmental Sustainability including Climate Change (These include World Bank Assisted Projects, FGN Supported Great Green World Projects, etc. | C43: 1 | D43: 3 | E43: 1 | F43: 1 | G43: 0 | H43: 0 | I43: 1 | J43: 0 | K43: ='19. Min. of Env'!I29 -> 0.78111111
A44: 4 | B44: Improve the Health Status of the Population through the Promotion of Environmental Health and Public Health Security | C44: 12 | D44: 17 | E44: 5 | F44: 7 | G44: 0 | H44: 0 | I44: 4 | J44: 1 | K44: ='19. Min. of Env'!I50 -> 0.73195769
...

Sheet 1. OHOS
A1: OFFICE OF THE HEAD OF SERVICE (Publi Service Reforms and Service Delivery Improvement Initiatives
A2: FULL YEAR [JANUARY TO DECEMBER 2024] PERFORMANCE ASSESSMENT
A3: No. of Ops | B3: Expected Outputs for Delivering the Outcome Targets | C3: Output KPIs | D3: Results No. | E3: 2024 Target | F3: Jan. - Dec Results | G3: Performance | H3: Adjusted Performance | I3: Evidences
A4: OUTPUT LEVEL FRAMEWORK - OFFICE OF THE HEAD OF SERVICE
A5: Commitment-1: Sustain Improvement of Public Service Delivery through an optimized State Civil Service by the Principles of rewards and sanctions
B6: Enhanced Personnel and Organizational Productivity through their mandates, job descriptions and performance target with Annual State Productivity Awards | C6: Organisational Productivity Level | D6: 1 | E6: 70 | F6: NA | G6: Not Assessed | H6: Not Assessed | I6: Measurement Yardstick not defined yet. | J6: What is the yardstick of measurement?
C7: No. of staff that are rewarded for recorded outstanding performance | D7: 2 | E7: 10 | F7: 0 | G7: =F7/E7 -> 0 | H7: =G7 -> 0 | J7: Is he a staff or citizen of Jigawa State?
C8: No. of staff that are sanctioned for recorded poor performance | D8: 3 | E8: 10 | F8: 10 | G8: =F8/E8 -> 1 | H8: =G8 -> 1 | I8: Scores of staff were sanctioned following recommendations by a Whitepaper Committee. The MDAs included Ministry of Health and Tertiary Educational Institutions
C9: No of MDAs introduced to Corporate Planning | D9: 4 | E9: 5 | F9: 5 | G9: =F9/E9 -> 1 | H9: =G9 -> 1 | I9: The organisational structures functions and mandates of MDAs superviced by HoS have been completed | J9: OHOS, Manpower Development & Training,
C10: Executive Orders Issued on Development and Implementation of Service Charters in MDAs (No. of E.O Provisions implemented | D10: 5 | E10: 10 | F10: 0 | G10: =F10/E10 -> 0 | H10: =G10 -> 0 | I10: Servicom not yet reactivated and Exe. Order Issued
C11: Number of comprehensive service charters in MDAs (New and Reviewed) with bi-annual report from SERVICOM | D11: 6 | E11: 10 | F11: 0 | G11: =F11/E11 -> 0 | H11: =G11 -> 0 | I11: Servicom will soon be reactivated
C12: Average Performance | I12: =AVERAGE(H6:H11) -> 0.4
A13: Commitment 2: Merit based Staff Recruitment in Ministries, Departments and Agencies (especially in professional and technical cadres) to fill critical manpower gaps in public service and other sectors to allow for optimal performance
A14: 2 | B14: New staff recruitment to fill criticall manpower gaps especially in Public Service Delivery Sectors | C14: % of staff needs that are met through recruitments across all MDAs | D14: 1 | E14: 5 | F14: 5 | G14: =F14/E14 -> 1 | H14: =G14 -> 1 | I14: 560 college of nursing and midwives, 827 in Ministry of Health - 1225 in Subeb - 272 First Class in MoHEST - 187 in Nomadic and 130 Vet Dr's in MoA | J14: This is looking for the staff needs of all MDAs in the State and what % of such needs were met.
C15: % of Recruited staff that are females | D15: 2 | E15: 10 | F15: 10 | G15: =F15/E15 -> 1 | H15: =G15 -> 1 | I15: PROVIDE NO. OF FEMALES AND TOTAL RECRUITMENT
C16: % of Recruited staff that are people with disabilities | D16: 3 | E16: 0.05 | F16: =28/3210 -> 0.0087227414 | G16: =F16/E16 -> 0.17445483 | H16: =G16 -> 0.17445483 | I16: 2No. Disabled in Momadic and 26 in SUBEB
C17: Skill/Manpower Gaps Analysis conducted across all MDAs and periodically updated (Number of MDAs covered / reviewed) | D17: 4 | E17: 91 | F17: 80 | G17: =F17/E17 -> 0.87912088 | H17: =G17 -> 0.87912088 | I17: 80 mainstream MDA workforce planning has been completed, the remaining 11 are tertiary instituitions and some health facilities | J17: Evidence needed - the MPA document
C18: Average Performance | I18: =AVERAGE(H14:H17) -> 0.76339393
A19: Commitment-3: Ensure effectiveness and Sustainability of the State Pension Schemes
A20: 3 | B20: Gratuity and Monthly Pension paid as when due | C20: Percentage of retired staff paid their gratuity as when due | D20: 1 | E20: 100 | F20: 98.98 | G20: =F20/E20 -> 0.9898 | H20: =G20 -> 0.9898 | I20: N6,965,000,000 was paid to 2642 out of about ….. persons were paid gratuity and death benefits.
C21: Percentage of retired staff paid their monthly pension as when due | D21: 2 | E21: 100 | F21: 100 | G21: =F21/E21 -> 1 | H21: =G21 -> 1 | I21: 17,029 pensioners were paid the sum of N6,965,912,178.17
C22: Conduct of ActuRIal Valuation | D22: 3 | G22: NA | H22: Not Assessed | I22: Upcoming Review of RF
C23: Implementation of ActuRIal Valuation Report | D23: 4 | G23: NA | H23: Not Assessed | I23: Upcoming Review of RF
C24: Average Performance | I24: =AVERAGE(H20:H23) -> 0.9949
A25: Commitment-4: Manpower and Human Resource Development in the State Public Service to ensure that MDAs are manned and managed by competent, proficient and skilled manpower
A26: 4 | B26: Human Recource Development in the State Public Service to ensure it is manned and managed by competent proficient, and skilled manpower in-line with the professional standards demanded by the peculiarities of each cadre for optimal performance | C26: No of training programmes implemented by the State MDI across various cadres in the State Civil Service | D26: 1 | E26: 18 | F26: 3 | G26: =F26/E26 -> 0.16666667 | H26: =G26 -> 0.16666667 | J26: Mention them (the training programmes)
C27: Number of Civil Servants Trained by State MDI across all MDAs covering various cadres | D27: 2 | E27: 540 | F27: 81 | G27: =F27/E27 -> 0.15 | H27: =G27 -> 0.15 | J27: Attendance sheet
C28: Total number of participated in short term Capacity Building Programme for Staff across MDAs | D28: 3 | E28: 300 | F28: 550 | G28: =F28/E28 -> 1.8333333 | H28: 1.01 | I28: 100 trained on e-governance, 50 on public service management, 150 on enhanding producitivity and 250 on digital transformation. | J28: Attendance sheet
C29: Number of staff trained on long term Programme through In-Service Training and other established collaborations with tertiary institutions. | D29: 4 | E29: 1000 | F29: 918 | G29: =F29/E29 -> 0.918 | H29: =G29 -> 0.918 | I29: 902 Inservice Training - 16 Doctors on Residency Training were sponsored | J29: Need for only 2024
C30: Number of staff trained through professional bodies on their task related skills | D30: 5 | E30: 150 | F30: 32 | G30: =F30/E30 -> 0.21333333 | H30: =G30 -> 0.21333333 | I30: Funds are limited to revolving payment of professional loan: N11,200,000 was paid to 32 applicants | J30: What is does this has to do with personal loan to staff?
C31: Repositioned and Improved Perforamance of the State MDI as assessed by No. of programmes mounted by the Institute across State MDAs, LGAs and others | D31: 6 | E31: 27 | F31: 5 | G31: =F31/E31 -> 0.18518519 | H31: =G31 -> 0.18518519 | J31: ??????
C32: Repositioned and Improved Perforamance of the State MDI as assessed by No. of people trained by the Institute across State MDAs, LGAs and others | D32: 7 | E32: 1080 | F32: 320 | G32: =F32/E32 -> 0.2962963 | H32: =G32 -> 0.2962963 | I32: The breakdown of additional 49 is as follows 32 Computer Certificate - 13 Professional Diploma and 4 Coding | J32: ??????
C33: Attainment of Annual Revenue Estimates (Targets as per Approved Budget) by the Manpower Development Institute | D33: 8 | E33: 90 | F33: 9.32 | G33: =F33/E33 -> 0.10355556 | H33: =G33 -> 0.10355556 | I33: Only about 54.72 million reported against a target of N587 million as per 2024 AFS which amounts to less than 10% | J33: =104.5/194 -> 0.53865979
C34: Annual growth in revenues generated by MDI | D34: 9 | E34: 10 | F34: 0 | G34: =F34/E34 -> 0 | H34: =G34 -> 0 | I34: Actual collection in 2023 was about N112.47 million against N54.72 in 2024 - declines of over 51.3% (2024 AFS)
C35: Resuscitated State Manpower Committee as assessed by qualitative bi-annual reports submitted to the State Executive Council | D35: 10 | E35: 4 | F35: 3 | G35: =F35/E35 -> 0.75 | H35: =G35 -> 0.75 | I35: 3 reports for workforce gap analysis were presented by the HoS to the State Exco (Workforce Technical Committee serving as Manpower Committee)
C36: Average Performance | I36: =AVERAGE(H26:H35) -> 0.3793037
C37: Overall Average Performance | G37: =AVERAGE(G27:G36) -> 0.49441152 | H37: =AVERAGE(H6:H36) -> 0.51601965
D43: a

Sheet 2. SSGs Office
A1: OFFICE OF THE SECRETARY TO THE STATE GOVERNMENT (SPECIAL SERVICES DIRECTORATE)
A2: FULL YEAR [JANUARY TO DECEMBER 2024] PERFORMANCE ASSESSMENT
A3: No. of Ops | B3: Expected Outputs for Delivering the Outcome Targets | C3: Output KPIs | D3: Results No. | E3: 2024 Target | F3: Jan. - Dec Results | G3: Performance | H3: Adjusted Performance | I3: Evidences
A4: Commitment 1: Work with the relevant agencies to create Jigawa State Joint Intelligence Fusion Center for command, communication and control under the relevant agencies to have a Single Security Coordination Center.
A5: 1 | B5: Sustained Support for Security Operations and Community Policing through effective collaboration between the State & Local Governments, Security Agencies, Emirate Councils, Local Vigilantes, and other Critical Stakeholders in the State Security Arctecture | C5: % Progress in streamlinng Joint Security Operations based on an Established and Functional Single Security Coordinating Center (SCC) | D5: 1 | E5: 0.6 | F5: 0.5 | G5: =F5/E5 -> 0.83333333 | H5: =G5 -> 0.83333333
C6: Number of community security cases and social vices (theft, robbery, drug-related offences, etc) cases intervened/mitigated through the Joint Security Operations | D6: 2 | E6: 20 | H6: NA | I6: Newly Set
C7: Number of potential conflicts & disputes (e.g., farmers/herders conflicts, border disputes, etc.) mitigated annually through Community-Policing and other proactive means with early-warning signals. | D7: 3 | E7: 10 | H7: NA | I7: Newly Set
C8: State Security Council meets at least Quarterly to consider reports and strategies for sustained security vigilance | D8: 4 | E8: 4 | F8: 4 | G8: =F8/E8 -> 1 | H8: =G8 -> 1
C9: No. of Targetted Stakeholder Engagements, including the Security Agencies, Traditional Institutions, and the Ulamas efforts to maintain Peace and Security in the State through effective collaboration and dialogue | D9: 5 | E9: 4 | F9: 3 | G9: =F9/E9 -> 0.75 | H9: =G9 -> 0.75 | I9: Three Meetings Held with Stakeholders from Guri Local Government on Peaceful Coexistence Between Farmers and Herdsmen Chaired by the Governor
H10: Average Score | I10: =AVERAGE(H8:H9) -> 0.875
A11: Commitment 2: Launch the Community Peace Initiative (CPI) as a performance- based grant to promote peacekeeping and attract development to the communities
A12: 2 | B12: Performance based grants given to CPIs for peace keeping performance | C12: Number of CPIs that have Received Performance Grants | D12: 6 | E12: 3 | G12: NA | H12: NA | I12: Not Yet Commenced
H13: Average Score | I13: NA
A14: Commitment 3: Empower the traditional institutions to maintain and regularly update the data of residents and newcomers to curtail and prevent the infiltration of criminals
A15: r | B15: Database of residents in the State updated | C15: Percentage of the population of residents whose data have been capture in the state security database | D15: 7 | E15: 50 | G15: NA | H15: =G15 -> NA | I15: Not Assessed
H16: Average Score | I16: NA
A17: Commitment 4: Facilitate partinerships between law enforcement tagencies and residents, there by improving trust between the law enforcement agencies and residenta and ignite the free flow of accurate information from the residents regarding criminal activities in thier community
A18: 4 | B18: Improve residents perception of trust on the law enforcement agencies | C18: Residents perception on confidence in security enforcement agencies (opinion pool) | D18: 8 | E18: 0 | G18: NA | H18: =G18 -> NA | I18: Not Assessed
H19: Average Score | I19: NA
A20: Commitment 5: Intergrate the various local security outfits and equip them with relavent non-lethal tools and better support in terms of logistics training and intellegece as part of the stratgy to improve our vigillance service.
A21: 5 | B21: Community Security guards officers intigated into the police system | C21: Number of Trained Community Security Guards recruited to support security efforts in Government Institutions and Public Places | D21: 9 | E21: 900 | F21: 900 | G21: =F21/E21 -> 1 | H21: =G21 -> 1 | I21: Over 9,000 Security Guard Officers recruited and trainined through private security agencies
C22: Propotion of the trained Community Security Guards integrated into formal security systems | D22: 10 | E22: 0.9 | F22: 1 | G22: =F22/E22 -> 1.1111111 | H22: 1.01 | I22: All 900 Security Guards were trained
H23: Average Score | I23: =AVERAGE(H21:H22) -> 1.005
A24: Commitment 6: Continued support for community policing and strengthening of preventive mechanisms with effective enforcement of the relevant criminal laws in justice system administration.
A25: 3 | B25: Support for the establishment of Community Securty Guards based on a PPP Model | C25: Percentage of Progresss towards the establishment and functionality of Community Security Guard Office (CSGO) for strengthened Community Based Security Architecture | D25: 11 | E25: 60 | F25: 60 | G25: =F25/E25 -> 1 | H25: =G25 -> 1 | I25: Assuming CSGO is equivelent of Hisba, this much progress was achieved following recruiment / appointment of key personnel and submission of Hisba Bill to HoA
C26: Number of Community Security Guards Recruited, Trained, Empwered and Drafted into Community Policing Annually | D26: 12 | E26: =27*30 -> 810 | F26: 900 | G26: =F26/E26 -> 1.1111111 | H26: 1.01 | I26: This is represented by the 900 Recruited Personnel for Government Institutions
H28: Average Score | I28: =AVERAGE(H25:H26) -> 1.005
A29: Commitment 7: Collaboration with the relevant Federal Agencies in dealing with security threats and youth drug abuse through the nefarious activities of drug dealers in the Communities.
A30: 4 | B30: MultiSectoral Approach in the Crusade Against Drug Abuse | C30: Establishment and Functionality of a MultiSectoral Taskforce on the Security Threats by Local Drug Dealers, Canpaign Agaist Drug Abuse and Rehabilitarion of Drug Addicts | D30: 13 | H30: Not Assessed | I30: Newly Set
C31: Number of Local Drug Dealers Apprehended | D31: 14 | H31: Not Assessed | I31: Newly Set
C32: Number of Activities Conducted in the Campsign Against Drug Abuse | D32: 15 | H32: Not Assessed | I32: Newly Set
A33: 1 | B33: Community Security guards officers intigated into the police system | C33: Propotion of the trained community security guards officers that have been integrated into formal police force | D33: 16 | E33: 60 | F33: 0 | G33: =F33/E33 -> 0 | H33: =G33 -> 0 | I33: Not Achieved
H34: Average Score | I34: =AVERAGE(H30:H33) -> 0
A35: Commitment 8: Introduce and Operationalize Jigawa Security Trust fund to increase financing and support to national and local security forces
A36: 2 | B36: Establishment of Security Trust Fund for improved funding and support to Security Agencies including the implementation of Performance-based grants for Community-based Peace Initiatives | C36: Percentage Progress towards the establishment and Functionality of Security Trust Fund (Establishment, Legal Backing and Operations | D36: 17 | E36: 20 | F36: 5 | G36: =F36/E36 -> 0.25 | H36: =G36 -> 0.25 | I36: Memo has already put in place and waiting for approval by His Excellecy based on discussion at the Expanded
C37: % Increase in Mobilized Financial Resources Above Initial Seed Funds | D37: 18 | E37: 0.2 | F37: 0 | G37: =F37/E37 -> 0 | H37: =G37 -> 0 | I37: No Assessed
C38: Number of Community-based Peace Initiatives Supported through the Performance-based Grants | D38: 19 | E38: 60 | F38: 0 | G38: =F38/E38 -> 0 | H38: Not Assessed | I38: Not Yet Commenced
H39: Average Score | I39: =AVERAGE(H36:H38) -> 0.125
G40: Aggregate Score | H40: =AVERAGE(H5:H39) -> 0.68533333

Sheet 3. Min. of Special Duties
A1: MINISTRY FOR SPECIAL DUTIES
A2: FULL YEAR [JANUARY TO DECEMBER 2024] PERFORMANCE ASSESSMENT
A3: No. of Ops | B3: Expected Outputs for Delivering the Outcome Targets | C3: Output KPIs | D3: RAs No. | E3: 2024 Target | F3: Jan. - Dec Results | G3: Performance | H3: Evidences | I3: Adjusted Performance | J3: Remarks / Evidances
A4: DELIVERY PERFORMANCE MANAGEMENT FRAMEWORK
A5: Commitment 1 - Effectively and Effeciently Execute Emergency Response & Prepraredness in dealing with any form of disaster or emergencies in the State
A7: 1 | B7: Improved Effeciency and Effectiveness of Emergency relief and Disaster Mangement | C7: Timeliness in Response to Disaster Occurance | D7: 1 | G7: N/A | I7: =G7 -> N/A | J7: Not Assessed
C8: Number of MoUs signed with either Local or international Partners on disaster management | D8: 2 | E8: 5 | F8: 2 | G8: =F8/E8 -> 0.4 | I8: =G8 -> 0.4 | J8: PPFN collaborated with State Emergency Management Agency of Jigawa state as well as the State Ministry of Health throughout the outreach.LGA OF IMPLEMENATION: MIGA, KIYAWA, GWARAM, DUTSE OBJECTIVES OF THE ACTIVITY (The activity objective is what the activity aims to do, for example provide your perspective or deliver some sort of experience for the young people you work with. 2.Partner: Relief Rescue Initiative (RRI) Project Title: Emergency WASH and Multipurpose Cash Assistance to flood-affected Community in Jigawa State Location: Jahun, Miga, Kiri kasamma, Buji and Gwarama
C9: Percentage of household victims that received relief package during emergency | D9: 3 | E9: 100 | F9: 100 | G9: =F9/E9 -> 1 | I9: =G9 -> 1 | J9: 38,078 victims has fully received relief package during emergency | K9: Conprehensive reports will be submitted
C10: State emergency policy developed and operationalised | D10: 4 | E10: 1 | F10: 1 | G10: =F10/E10 -> 1 | I10: =G10 -> 1 | J10: Emergency Contingency Plan developed and publishe with support of UNICEF.
A11: 2 | B11: Emergency mangement committee established at State level in 27 local Government and at a ward level in specific flood-prone areas | C11: Numberof local Government that have fuctional emergency management committee | D11: 5 | E11: 12 | F11: 27 | G11: =F11/E11 -> 2.25 | I11: 1.01 | J11: LEMCs estarblished and trained across the 27 LGAs
C12: Percentage of political wards that have fuctional Emergency management committee | D12: 6 | E12: 20 | F12: 0 | G12: =F12/E12 -> 0 | I12: =G12 -> 0
C13: Average Performance
A15: DELIVERY PERFORMANCE MANAGEMENT FRAMEWORK
A16: Commitmen 2 Effectively and Effeciently Provide Support to Citizens of Jigawa State Seeking Enlistment in the Military, Paramilitary Organzations and Federal Establishments including the Provision of Guidance & Counselling Support to Youths in Jigawa State
A17: No. of Ops | B17: Expected Outputs for Delivering the Outcome Targets | C17: Output KPIs | D17: RAs No. | E17: 2024 Target | F17: Jan. - Dec Results | G17: Performance | H17: Evidences | J17: Remarks / Evidances
A18: 3 | B18: Support towards the placement of Citizens of Jigawa State in the Military, Paramilitary and other Federal Establishment | C18: No. of Jigawa Citizens Supported to be Enrolled in Military, Paramilitary and Federal Establishments | D18: 7 | E18: 1500 | F18: 1947 | G18: =F18/E18 -> 1.298 | H18: =G18/F18 -> 0.00066666667 | I18: 1.01 | J18: Target achieved due to the commitment of present administration in order to provide more employment.
C19: No. of Engagements with Federal Character Commission through the State Representative in the Employment of Jigawa Citizens in Federal Agencies | D19: 8 | E19: 6 | F19: 2 | G19: =F19/E19 -> 0.33333333 | H19: =G19/F19 -> 0.16666667 | I19: =G19 -> 0.33333333 | J19: Evidence and what was the outcome
A20: 4 | B20: Guidance and Counselling Support to Youths in Jigawa State | C20: No of Guidance & Counselling Activities Conducted across all the 27 LGAs in the State | D20: 9 | E20: 54 | F20: 10 | G20: =F20/E20 -> 0.18518519 | H20: =G20/F20 -> 0.018518519 | I20: =G20 -> 0.18518519 | J20: What are the LGs
C21: Average Performance
A22: DELIVERY PERFORMANCE MANAGEMENT FRAMEWORK
A23: Commitment 3 - Effectively and Effeciently Execute any Duty of Special Natuture required for the overall socioeconomi welbeing of the citizens of Jigawa State
A24: No. of Ops | B24: Expected Outputs for Delivering the Outcome Targets | C24: Output KPIs | D24: RAs No. | E24: 2024 Target | F24: Jan. - Dec Results | G24: Performance | H24: Evidences | J24: Remarks / Evidances
A25: 5 | B25: Effective Discharge of Other Special Duties | C25: No. of Palliative Shops Established in each LGA Headquarter | D25: 10 | E25: 27 | F25: 27 | G25: =F25/E25 -> 1 | I25: =G25 -> 1 | J25: Palliative Shops Established in each LGA and Headquarter
C26: No. of Palliative Shops Established in all 287 Political Wards in the State | D26: 11 | E26: 287 | F26: 27 | G26: =F26/E26 -> 0.094076655 | I26: =G26 -> 0.094076655 | J26: Ongoing project
C27: No. of other Major Special Duties Successfully Executed | D27: 12 | E27: 6 | F27: 1 | G27: =F27/E27 -> 0.16666667 | I27: =G27 -> 0.16666667 | J27: Free Ramadan feeding is provided across 27 LGAs iun 639 centres
C28: Average Performance | I28: =AVERAGE(I7:I27) -> 0.56356926

Sheet 4. Min. of LG
A1: MINISTRY FOR LOCAL GOVERNMENT & COMMUNITY DEVELOPMENT
A2: FULL YEAR [JANUARY TO DECEMBER 2024] PERFORMANCE ASSESSMENT
A3: DELIVERY PERFORMANCE MANAGEMENT FRAMEWORK
A4: No. of Ops | B4: Expected Outputs for Delivering the Outcome Targets | C4: Output KPIs | D4: No. of RAs | E4: 2024 Target | F4: Jan - Dec Results | G4: Performance | H4: Adjusted Performance | I4: Remarks / Evidences
A5: Commitment 1: Strengthen Community Based Security Architecture
A7: 1 | B7: Community Guards Coordinating Unit established and Fuctional at State and Local Governments | C7: Number of Local Governments Councils that have Functional Community Guards Coordinating Units. | D7: 1 | E7: 6 | F7: 10 | G7: =F7/E7 -> 1.6666667 | H7: 1.01 | I7: There are Six (6) LGCs in the State that have Functional Community Guards Coordinating Units, the Local Government are Mallam Madori, Kafin Hausa, Birnin Kudu, Maigatari, Kaugama, Yankwashi, Gumel, Birniwa, Gwaram, and Guri Local Government Councils.
I8: =AVERAGE(H7) -> 1.01
A9: Commitment 2: Launch the Community Peace Initiative (CPI)as a Performance-based grant to improve service delivery and overall socioeconomic development at the Community level
A10: 2 | B10: Support Community Based Projects across the State | C10: Number of Community Led Projects Financed | D10: 1 | E10: 50 | F10: 23 | G10: =F10/E10 -> 0.46 | H10: =G10 -> 0.46 | I10: There are twenty one (21)No. Community Led Project Financed in the Ten ( 10) LGAs in the State. The Supported Communities include the following: 1 - Kungiyar Cigaban Kewaye, Lafiya Ward - The Constructed a Mosque to Linter Stage. 2 - Lafiya Youth Association - The Constructed a Mosques to Linter Stage. 3 - Birnin Kudu Youth Association - They Planted 2,000 Trees at FMC Birnin Kudu New Site. 4 - Mafitar Matasan Birnin Kudu Yau da Gobe - They Cleared Grave Yard at Birnin Kudu and Cleared Grasses at Birnin kudu General Hospital. 5 - Kaugama Development Association - Support in the Completion of Kaugama Central Mosque. 6 - Gawon Bariki Development Association (Dakayyawa) - The Constructed Islamiyya School to Linter Statge. 7 - Hospital Friends Committee - The Constructed One Block to Linter Stage at Kafin HausaaGenenal Hospital. 8 - Dantanoma Self-Help Group - The Constrcted Islamiyya School to Linter Stage. 9 - Mele Development Association - They Constructed Mosque to Linter Stage. 10 - Maigatari Development Association - They Constructed Mosque to Linter. 11 - Maigatari Foundation - They Constructed Islamiyya School to Linter Statge. 12 - Sabuwar Unguwar Kiyawa Self-help Group - They Constructed Mosque to Linter Stage. 13 - Kungiyar Cigaban Unguwar Galadanci - They Constructed 1/3 Mosque. 14 - Gumel Emirate Foundation - Four LGAs from the emirate Renovated and completed the Main Building and Guess Rooms for the Organistion.
I11: 9- MELE DEVELOPMENT ASSOCIATION. They Constructed Mosque to Linter Stage. 10- MAIGATARI DEVELOPMENT ASSOCIATION. They Constructed Mosque to Linter. 11- MAIGATARI FOUNDATION. They Constructed Islamiyya School TO Linter Statge. 12- SABUWAR UNGUWA KIYAWA SELP-HELP GROUP. They Constructed Mosque to Linter Stage. 13- KUNGIYAR CIGABAN UNGUWAR GALADANCI. They Constructed 1/3 Mosque. 14- GUMEL EMIRATE FOUNDATION .four LGAs from the emirate Renovated and completed the Main Building and Guess Rooms for the Organistion
I12: 15- BIRNIN KUDU YOUTH ASSOCIATION (B.Y.A) has constructed Islamiyya to Linter Stage and Completed by the Birnin Kudu Local Govt. 16 - MURYA BIRNIN KUDU has renovated 2blocks at Zango Primary School Birnin Kudu 17 - KAYA DEVELOPMENT ASSOCIATION Garki L.G Constructed Friday Mosque to Linter at KAYA Village 18 - NATO MOTOR PARK DUTSE L.G constructed a Five (5) daily prayer Mosque to linter stage at the Motor park. 19 - SULE TANKARKAR SERLF GROUP: Constructed a five (5) daily Prayer Mosque to Completion Stage at Sule Tankarkar Town. 20 - ALTIMA MALAM UBALI SEVEN DEVELOPMENT ASSOCIATION : Constructed 1block of Islamiyya school to completion stage at Babura Town 21 - LAFKA SELF HELP GROUP Kaugama LG Constructed a five daily Prayer Mosque To Completion Stage at Kagama.
I13: =AVERAGE(H10:H13) -> 0.46
A14: Commitment 3: Create an Elders Advisory Committee (ELCO) in every Local Government to Advise Government On variours government programs and implementations strategies for
A15: 3 | B15: Elders Advisory Committee Fuctional in the 27 Local Governments | C15: Number of Locsl Government Councils with Functional Elders Advisory Committee. | D15: 1 | E15: 10 | F15: 6 | G15: =F15/E15 -> 0.6 | H15: =G15 -> 0.6 | I15: We mobilised self help Group and Development Associations Toward Communty engagement in Government Policies and Objectives at 6 Local Government of the state. The six Local Government Include: HADEJIA, BIRNIN KUDU, GUMEL, KAZAURE, KIYAWA AND RINGIM. - The Elders Advisory Committe Established in OCTOBER 2024 and the Names of the Community Members will be collected after the completion of the 21 Local Government of the State for inauguration by FEB 2025 and Functional at the same Month. - There is also a refresentatives of One persons from each Wards Across the State and the committee set of 2 women as Gender Refresentatives from each LG. - Therefore the Committee consisted of 12No. Persons From each Local Government.
I16: =AVERAGE(H15) -> 0.6
A17: Commitment 4: Entrench an effective financial management system alongside improved policy and strategy across all the Local Governments with the support and collaboration with Development Partners.
A18: 4 | B18: Development Plan Formulated for the 27 Local Governments. | C18: Percentage of LGA that have Developed First Generation Local Government Development Plan (LGDP) | D18: 1 | E18: 100 | F18: 80 | G18: =F18/E18 -> 0.8 | H18: =G18 -> 0.8 | I18: All the 27 LGCs have Developed First Generation Local Government Development Plan, and the Validation and Printed will soon be undertaken
C19: Percentage of LGA that upgraded their Annual Buddget to IPSAS Standards based on National Chart of Accounts | D19: 2 | E19: 40 | F19: 35 | G19: =F19/E19 -> 0.875 | H19: =G19 -> 0.875 | I19: All the 27 LGCs has upgraded their programmers of budgeting to the IPSAS Accounting Standards and 2023 , 2024 and 2025 Budget are in form of IPSAS .
C20: Performance | I20: =AVERAGE(H18:H19) -> 0.8375
A22: Commitment-5: Sustain Improvement of Public Service Delivery and Institutional Reforms at the Local Government Level (Street Lghts, Water Supply, SERVICOM, etc)
A23: 5 | B23: Functionality of LGA Streetlights across the LGAs (Maintenance, Diesel, etc) | C23: Average number hours Streetlights function on a daily Basis | D23: 1 | E23: 12 | F23: 11 | G23: =F23/E23 -> 0.91666667 | H23: =G23 -> 0.91666667 | I23: The Streetlight are Functioning 11 Hours daily but initial Hours is from 6 to 6, due to change of whether, sometime Longer day shorter night.
A24: 6 | C24: Number of Diesel Streetlight Projects Converted to Solar | D24: 2 | E24: 15 | G24: =F24/E24 -> 0 | H24: =G24 -> 0 | I24: No any Diesel Streetlight Converted to Solar, but resolved to be undertaken in 2025 fiscal year and were already captured in the Approved Budget. There are 10 LGAs that areto be covered. The LGAs Include: GUMEL, HADEJIA, RINGIM, KAZAURE, RONI, AUYO, GAGARAWA, TAURA, KAFIN HAUSA AND KIYAWA .
A25: 7 | C25: Number of days before non-funtional Streetlights in LGAs are Fixed. | D25: 3 | E25: 14 | F25: 14 | G25: =F25/E25 -> 1 | H25: =G25 -> 1 | I25: Is Fourteen Days (14) before non-Functional Streetlights in LGCs are Fixed Armour Cables are Regularly Distributed to all 27 Local Governments according to their demand
I27: =AVERAGE(H23:I25) -> 0.63888889
C28: Performance
C29: Overall Performance | H29: =AVERAGE(H7:H28) -> 0.70770833

Sheet 5. Min. of Budget
A1: JIGAWA STATE MINISTRY OF BUDGET & ECONOMIC PLANNING
A2: FULL YEAR [JANUARY TO DECEMBER 2024] PERFORMANCE ASSESSMENT
A3: No. of Ops | B3: Expected Outputs for Delivering the Outcome Targets | C3: Output KPIs | D3: Results No. | E3: 2024 Target | F3: Jan -Dec Actuals | G3: Performance | H3: Adjusted Performance | I3: Remarks / Evidances
A4: DELIVERY PERFORMANCE MANAGEMENT FRAMEWORK
A5: Commitment 1: Commitment 1: Mobilization of Local and International Development Organizationand Effective Donor coordination
A7: 1 | B7: The scope of development support and technical assistance with International Development Partners widened | C7: Number of Development Partners / Programs Operating in the State | D7: 1 | E7: 25 | F7: 25 | G7: =F7/E7 -> 1 | H7: =G7 -> 1 | I7: List of Development Partners available
C8: Number of Programmes being supported by Development Partners in the State (exisiting and new). | D8: 2 | E8: 33 | F8: 42 | G8: =F8/E8 -> 1.2727273 | H8: 1.01 | I8: Programmes supported by Development Partners provided
C9: Increase in the Quantum of Resources coming to the State from Development Partners | D9: 3 | E9: 100 | G9: NA | H9: =G9 -> NA | I9: Not Assessed
C10: Percentage of financing gap of State Development plan filled by the ODA | D10: 4 | E10: 70 | F10: 24 | G10: NA | H10: =G10 -> NA | I10: Not Assessed
C11: Functionality of Development Partners Forum (Percentage of Quarterly Meetings Conducted) | D11: 5 | E11: 4 | F11: 0 | G11: =F11/E11 -> 0 | H11: =G11 -> 0
C12: Extent of JIMAF Implementation across MDAs and Initiatives | D12: 6 | E12: 90 | F12: 40 | G12: =F12/E12 -> 0.44444444 | H12: =G12 -> 0.44444444 | I12: Assumed
C13: Performance | I13: =AVERAGE(H7:H12) -> 0.61361111 | J13: =I13 -> 0.61361111
A14: Commitment 2: Improved Governance & Accountability through sustained Public Expenditure and Financial Management Reforms / Fiscal Sustainability.
A15: 2 | B15: Establishment of a Functional PFM Core Group to Sustain Fiscal and Financial Management Reforms. | C15: Functionality of PFM Core Group (Minmum of 4 Quarterly Meetings and 2 Key Governance Reform Activities such as Training Workshops) | D15: 1 | E15: 7 | F15: 3 | G15: =F15/E15 -> 0.42857143 | H15: =G15 -> 0.42857143 | I15: Only three PFM Core Groups Meetings Held during the year
C16: Conduct of Annual Report on Rapid Performance Assessment of PFM Indicators and Percentage Target Score of 75% | D16: 2 | E16: 75 | F16: 0 | G16: =F16/E16 -> 0 | H16: =G16 -> 0 | I16: RAPID PFM Assessment Not condicted
